<?xml version="1.0"?>
<robot xmlns:xacro="http://www.ros.org/wiki/xacro" name="amr_robot">

  <!-- ================= CONSTANTS ================= -->
  <xacro:property name="wheel_radius" value="0.05"/>
  <xacro:property name="wheel_separation" value="0.30"/>
  <xacro:property name="base_mass" value="10.0"/>

  <!-- ================= ROOT LINK ================= -->
  <link name="base_footprint"/>

  <!-- ================= BASE LINK ================= -->
  <link name="base_link">
    <visual>
      <geometry>
        <box size="0.4 0.3 0.1"/>
      </geometry>
    </visual>
    <collision>
      <geometry>
        <box size="0.4 0.3 0.1"/>
      </geometry>
    </collision>
    <inertial>
      <mass value="${base_mass}"/>
      <inertia
        ixx="0.1"
        iyy="0.1"
        izz="0.1"
        ixy="0.0"
        ixz="0.0"
        iyz="0.0"/>
    </inertial>
  </link>

  <joint name="base_link_joint" type="fixed">
    <parent link="base_footprint"/>
    <child link="base_link"/>
    <origin xyz="0 0 0.05"/>
  </joint>

  <!-- ================= LEFT WHEEL ================= -->
  <link name="left_wheel">
    <visual>
      <geometry>
        <cylinder radius="${wheel_radius}" length="0.03"/>
      </geometry>
    </visual>
    <collision>
      <geometry>
        <cylinder radius="${wheel_radius}" length="0.03"/>
      </geometry>
    </collision>
    <inertial>
      <mass value="1.0"/>
      <inertia
        ixx="0.001"
        iyy="0.001"
        izz="0.001"
        ixy="0.0"
        ixz="0.0"
        iyz="0.0"/>
    </inertial>
  </link>

  <joint name="left_wheel_joint" type="continuous">
    <parent link="base_link"/>
    <child link="left_wheel"/>
    <origin xyz="0 0.15 0"/>
    <axis xyz="1 0 0"/>
  </joint>

  <!-- ================= RIGHT WHEEL ================= -->
  <link name="right_wheel">
    <visual>
      <geometry>
        <cylinder radius="${wheel_radius}" length="0.03"/>
      </geometry>
    </visual>
    <collision>
      <geometry>
        <cylinder radius="${wheel_radius}" length="0.03"/>
      </geometry>
    </collision>
    <inertial>
      <mass value="1.0"/>
      <inertia
        ixx="0.001"
        iyy="0.001"
        izz="0.001"
        ixy="0.0"
        ixz="0.0"
        iyz="0.0"/>
    </inertial>
  </link>

  <joint name="right_wheel_joint" type="continuous">
    <parent link="base_link"/>
    <child link="right_wheel"/>
    <origin xyz="0 -0.15 0"/>
    <axis xyz="1 0 0"/>
  </joint>

  <!-- ================= IMU ================= -->
  <link name="imu_link">
    <inertial>
      <mass value="0.1"/>
      <inertia
        ixx="0.0001"
        iyy="0.0001"
        izz="0.0001"
        ixy="0.0"
        ixz="0.0"
        iyz="0.0"/>
    </inertial>
  </link>

  <joint name="imu_joint" type="fixed">
    <parent link="base_link"/>
    <child link="imu_link"/>
    <origin xyz="0 0 0.05"/>
  </joint>

  <!-- ================= LIDAR ================= -->
  <link name="laser_link">
    <inertial>
      <mass value="0.1"/>
      <inertia
        ixx="0.0001"
        iyy="0.0001"
        izz="0.0001"
        ixy="0.0"
        ixz="0.0"
        iyz="0.0"/>
    </inertial>
  </link>

  <joint name="laser_joint" type="fixed">
    <parent link="base_link"/>
    <child link="laser_link"/>
    <origin xyz="0.15 0 0.1"/>
  </joint>

  <!-- ================= GAZEBO PLUGINS ================= -->

  <!-- Diff Drive -->
  <gazebo>
    <plugin name="diff_drive" filename="libgazebo_ros_diff_drive.so">

      <!-- Wheel joints -->
      <left_joint>left_wheel_joint</left_joint>
      <right_joint>right_wheel_joint</right_joint>

      <!-- Geometry -->
      <wheel_separation>0.30</wheel_separation>
      <wheel_radius>0.05</wheel_radius>

      <!-- ROS 2 topics -->
      <command_topic>cmd_vel</command_topic>
      <odometry_topic>odom</odometry_topic>

      <!-- Frames -->
      <odometry_frame>odom</odometry_frame>
      <robot_base_frame>base_footprint</robot_base_frame>

      <!-- Publishing -->
      <publish_odom>true</publish_odom>
      <publish_odom_tf>true</publish_odom_tf>
      <publish_wheel_tf>false</publish_wheel_tf>

      <!-- Timing -->
      <update_rate>50</update_rate>

    </plugin>
  </gazebo>

  <!-- IMU -->
  <gazebo reference="imu_link">
    <sensor name="imu_sensor" type="imu">
      <always_on>true</always_on>
      <update_rate>100</update_rate>
      <visualize>false</visualize>

      <imu>
        <angular_velocity>
          <x>
            <noise type="gaussian">
              <mean>0.0</mean>
              <stddev>0.0002</stddev>
            </noise>
          </x>
          <y>
            <noise type="gaussian">
              <mean>0.0</mean>
              <stddev>0.0002</stddev>
            </noise>
          </y>
          <z>
            <noise type="gaussian">
              <mean>0.0</mean>
              <stddev>0.0004</stddev>
            </noise>
          </z>
        </angular_velocity>

        <linear_acceleration>
          <x>
            <noise type="gaussian">
              <mean>0.0</mean>
              <stddev>0.02</stddev>
            </noise>
          </x>
          <y>
            <noise type="gaussian">
              <mean>0.0</mean>
              <stddev>0.02</stddev>
            </noise>
          </y>
          <z>
            <noise type="gaussian">
              <mean>0.0</mean>
              <stddev>0.04</stddev>
            </noise>
          </z>
        </linear_acceleration>
      </imu>

      <plugin name="imu_plugin" filename="libgazebo_ros_imu_sensor.so">
        <ros>
          <remapping>~/out:=imu/data</remapping>
        </ros>
        <frame_name>imu_link</frame_name>
      </plugin>
    </sensor>
  </gazebo>

  <!-- LIDAR -->
  <gazebo reference="laser_link">
    <plugin name="lidar_plugin" filename="libgazebo_ros_ray_sensor.so">
      <ros>
        <remapping>scan:=scan</remapping>
      </ros>
      <frame_name>laser_link</frame_name>
    </plugin>
  </gazebo>

</robot>
